<robot
  name="URDF_Silvia_collision.SLDASM">
  <link
    name="torso">
    <inertial>
      <origin
        xyz="-4.68079258277575E-18 -2.69675254928862E-17 -0.0425442477859752"
        rpy="0 0 0" />
      <mass
        value="12.0920235675445" />
      <inertia
        ixx="0.149172696646228"
        ixy="-2.5020559168504E-17"
        ixz="-1.50790596551797E-17"
        iyy="0.147816950326144"
        iyz="1.24842616648858E-17"
        izz="0.280065401777615" />
    </inertial>
    <visual>
      <origin
        xyz="0 0 0"
        rpy="0 0 0" />
      <geometry>
        <mesh
          filename="package://URDF_Silvia_collision.SLDASM/meshes/torso.STL" />
      </geometry>
      <material
        name="">
        <color
          rgba="0.792156862745098 0.819607843137255 0.933333333333333 1" />
      </material>
    </visual>
    <collision>
      <origin
        xyz="0 0 0"
        rpy="0 0 0" />
      <geometry>
        <mesh
          filename="package://URDF_Silvia_collision.SLDASM/meshes/torso.STL" />
      </geometry>
      <contact_coefficient mu="0" k_p="0" k_d="0" />
    </collision>
  </link>
  <link
    name="RF_Coxa">
    <inertial>
      <origin
        xyz="0.034 1.38777878078145E-17 -6.93889390390723E-18"
        rpy="0 0 0" />
      <mass
        value="0.1274" />
      <inertia
        ixx="9.62400833333334E-05"
        ixy="3.38813178901715E-21"
        ixz="-1.02047932905951E-20"
        iyy="0.000114458283333333"
        iyz="8.89131936292817E-21"
        izz="3.48651333333333E-05" />
    </inertial>
    <visual>
      <origin
        xyz="0 0 0"
        rpy="0 0 0" />
      <geometry>
        <mesh
          filename="package://URDF_Silvia_collision.SLDASM/meshes/RF_Coxa.STL" />
      </geometry>
      <material
        name="">
        <color
          rgba="0.792156862745098 0.819607843137255 0.933333333333333 1" />
      </material>
    </visual>
    <collision>
      <origin
        xyz="0 0 0"
        rpy="0 0 0" />
      <geometry>
        <mesh
          filename="package://URDF_Silvia_collision.SLDASM/meshes/RF_Coxa.STL" />
      </geometry>
    </collision>
  </link>
  <joint
    name="RF_Coxa"
    type="revolute">
    <origin
      xyz="0.110395052406582 0.191205694483979 -0.0411"
      rpy="-5.39663103724332E-16 -1.08690163350401E-15 1.04719755119655" />
    <parent
      link="torso" />
    <child
      link="RF_Coxa" />
    <axis
      xyz="0 0 1" />
  </joint>
  <link
    name="RF_Femur">
    <inertial>
      <origin
        xyz="0.10975 4.16333634234434E-17 -4.16333634234434E-17"
        rpy="0 0 0" />
      <mass
        value="0.750031499999998" />
      <inertia
        ixx="0.000552588207729998"
        ixy="-7.76441592278292E-19"
        ixz="-2.71050543121376E-19"
        iyy="0.00346297356378124"
        iyz="5.76574357467156E-20"
        izz="0.00311239884026124" />
    </inertial>
    <visual>
      <origin
        xyz="0 0 0"
        rpy="0 0 0" />
      <geometry>
        <mesh
          filename="package://URDF_Silvia_collision.SLDASM/meshes/RF_Femur.STL" />
      </geometry>
      <material
        name="">
        <color
          rgba="0.792156862745098 0.819607843137255 0.933333333333333 1" />
      </material>
    </visual>
    <collision>
      <origin
        xyz="0 0 0"
        rpy="0 0 0" />
      <geometry>
        <mesh
          filename="package://URDF_Silvia_collision.SLDASM/meshes/RF_Femur.STL" />
      </geometry>
    </collision>
  </link>
  <joint
    name="RF_Femur"
    type="revolute">
    <origin
      xyz="0.0569999999999997 0.000499999999999855 0"
      rpy="1.5707963267949 4.81153331183249E-16 -1.03805852802452E-14" />
    <parent
      link="RF_Coxa" />
    <child
      link="RF_Femur" />
    <axis
      xyz="0 0 1" />
  </joint>
  <link
    name="RF_Tibia">
    <inertial>
      <origin
        xyz="5.55111512312578E-17 -0.131709927052439 2.1467203015213E-17"
        rpy="0 0 0" />
      <mass
        value="0.27249436862269" />
      <inertia
        ixx="0.00410733533858373"
        ixy="5.55509832270988E-20"
        ixz="-2.10648587667354E-33"
        iyy="8.81242945143448E-05"
        iyz="-1.02629968190585E-18"
        izz="0.00404604861308373" />
    </inertial>
    <visual>
      <origin
        xyz="0 0 0"
        rpy="0 0 0" />
      <geometry>
        <mesh
          filename="package://URDF_Silvia_collision.SLDASM/meshes/RF_Tibia.STL" />
      </geometry>
      <material
        name="">
        <color
          rgba="0.792156862745098 0.819607843137255 0.933333333333333 1" />
      </material>
    </visual>
    <collision>
      <origin
        xyz="0 0 0"
        rpy="0 0 0" />
      <geometry>
        <mesh
          filename="package://URDF_Silvia_collision.SLDASM/meshes/RF_Tibia.STL" />
      </geometry>
    </collision>
  </link>
  <joint
    name="RF_Tibia"
    type="revolute">
    <origin
      xyz="0.197499999999995 -0.026499999999987 -0.000500000000000222"
      rpy="-1.71078416456661E-16 3.88578058618805E-16 4.28840521945901E-16" />
    <parent
      link="RF_Femur" />
    <child
      link="RF_Tibia" />
    <axis
      xyz="0 0 1" />
  </joint>
  <link
    name="RM_Coxa">
    <inertial>
      <origin
        xyz="0.0339999999999999 -1.65340831304039E-18 0"
        rpy="0 0 0" />
      <mass
        value="0.1274" />
      <inertia
        ixx="9.62400833333333E-05"
        ixy="8.95313825247795E-22"
        ixz="2.55795421013709E-21"
        iyy="0.000114458283333333"
        iyz="1.00586946902524E-20"
        izz="3.48651333333334E-05" />
    </inertial>
    <visual>
      <origin
        xyz="0 0 0"
        rpy="0 0 0" />
      <geometry>
        <mesh
          filename="package://URDF_Silvia_collision.SLDASM/meshes/RM_Coxa.STL" />
      </geometry>
      <material
        name="">
        <color
          rgba="0.792156862745098 0.819607843137255 0.933333333333333 1" />
      </material>
    </visual>
    <collision>
      <origin
        xyz="0 0 0"
        rpy="0 0 0" />
      <geometry>
        <mesh
          filename="package://URDF_Silvia_collision.SLDASM/meshes/RM_Coxa.STL" />
      </geometry>
    </collision>
  </link>
  <joint
    name="RM_Coxa"
    type="revolute">
    <origin
      xyz="0.221136515003529 -0.000204145205102327 -0.0411"
      rpy="0 0 0" />
    <parent
      link="torso" />
    <child
      link="RM_Coxa" />
    <axis
      xyz="0 0 1" />
  </joint>
  <link
    name="RM_Femur">
    <inertial>
      <origin
        xyz="0.10975 3.46944695195361E-17 -4.01154803819637E-18"
        rpy="0 0 0" />
      <mass
        value="0.750031499999999" />
      <inertia
        ixx="0.000552588207729999"
        ixy="-9.52515740004141E-19"
        ixz="7.49560100606101E-20"
        iyy="0.00346297356378124"
        iyz="-5.78338501845331E-21"
        izz="0.00311239884026124" />
    </inertial>
    <visual>
      <origin
        xyz="0 0 0"
        rpy="0 0 0" />
      <geometry>
        <mesh
          filename="package://URDF_Silvia_collision.SLDASM/meshes/RM_Femur.STL" />
      </geometry>
      <material
        name="">
        <color
          rgba="0.792156862745098 0.819607843137255 0.933333333333333 1" />
      </material>
    </visual>
    <collision>
      <origin
        xyz="0 0 0"
        rpy="0 0 0" />
      <geometry>
        <mesh
          filename="package://URDF_Silvia_collision.SLDASM/meshes/RM_Femur.STL" />
      </geometry>
    </collision>
  </link>
  <joint
    name="RM_Femur"
    type="revolute">
    <origin
      xyz="0.0569999999999996 0.000499999999999927 0"
      rpy="1.5707963267949 -5.90596833235144E-16 -1.0265205189556E-14" />
    <parent
      link="RM_Coxa" />
    <child
      link="RM_Femur" />
    <axis
      xyz="0 0 1" />
  </joint>
  <link
    name="RM_Tibia">
    <inertial>
      <origin
        xyz="0 -0.131709927052439 -2.23345647532014E-17"
        rpy="0 0 0" />
      <mass
        value="0.27249436862269" />
      <inertia
        ixx="0.00410733533858373"
        ixy="1.4146204583262E-20"
        ixz="-1.1561791260814E-20"
        iyy="8.81242945143448E-05"
        iyz="-6.46643452577581E-19"
        izz="0.00404604861308373" />
    </inertial>
    <visual>
      <origin
        xyz="0 0 0"
        rpy="0 0 0" />
      <geometry>
        <mesh
          filename="package://URDF_Silvia_collision.SLDASM/meshes/RM_Tibia.STL" />
      </geometry>
      <material
        name="">
        <color
          rgba="0.792156862745098 0.819607843137255 0.933333333333333 1" />
      </material>
    </visual>
    <collision>
      <origin
        xyz="0 0 0"
        rpy="0 0 0" />
      <geometry>
        <mesh
          filename="package://URDF_Silvia_collision.SLDASM/meshes/RM_Tibia.STL" />
      </geometry>
    </collision>
  </link>
  <joint
    name="RM_Tibia"
    type="revolute">
    <origin
      xyz="0.197499999999995 -0.0264999999999865 -0.000499999999992858"
      rpy="4.05010841783846E-16 -1.52144132255913E-14 -5.91889470417481E-16" />
    <parent
      link="RM_Femur" />
    <child
      link="RM_Tibia" />
    <axis
      xyz="0 0 1" />
  </joint>
  <link
    name="RR_Coxa">
    <inertial>
      <origin
        xyz="0.034 2.77555756156289E-17 0"
        rpy="0 0 0" />
      <mass
        value="0.1274" />
      <inertia
        ixx="9.62400833333335E-05"
        ixy="6.77626357803444E-21"
        ixz="-5.40705042229183E-21"
        iyy="0.000114458283333334"
        iyz="1.24645831963832E-20"
        izz="3.48651333333334E-05" />
    </inertial>
    <visual>
      <origin
        xyz="0 0 0"
        rpy="0 0 0" />
      <geometry>
        <mesh
          filename="package://URDF_Silvia_collision.SLDASM/meshes/RR_Coxa.STL" />
      </geometry>
      <material
        name="">
        <color
          rgba="0.792156862745098 0.819607843137255 0.933333333333333 1" />
      </material>
    </visual>
    <collision>
      <origin
        xyz="0 0 0"
        rpy="0 0 0" />
      <geometry>
        <mesh
          filename="package://URDF_Silvia_collision.SLDASM/meshes/RR_Coxa.STL" />
      </geometry>
    </collision>
  </link>
  <joint
    name="RR_Coxa"
    type="revolute">
    <origin
      xyz="0.110741462568083 -0.191813984894186 -0.0411"
      rpy="1.04921130408763E-15 -3.33066907387547E-16 -1.04719755119661" />
    <parent
      link="torso" />
    <child
      link="RR_Coxa" />
    <axis
      xyz="0 0 1" />
  </joint>
  <link
    name="RR_Femur">
    <inertial>
      <origin
        xyz="0.10975 3.46944695195361E-17 -1.38777878078145E-17"
        rpy="0 0 0" />
      <mass
        value="0.750031499999999" />
      <inertia
        ixx="0.000552588207729999"
        ixy="-7.43933951545773E-19"
        ixz="-2.7105054312137E-20"
        iyy="0.00346297356378125"
        iyz="-1.03832798067396E-20"
        izz="0.00311239884026125" />
    </inertial>
    <visual>
      <origin
        xyz="0 0 0"
        rpy="0 0 0" />
      <geometry>
        <mesh
          filename="package://URDF_Silvia_collision.SLDASM/meshes/RR_Femur.STL" />
      </geometry>
      <material
        name="">
        <color
          rgba="0.792156862745098 0.819607843137255 0.933333333333333 1" />
      </material>
    </visual>
    <collision>
      <origin
        xyz="0 0 0"
        rpy="0 0 0" />
      <geometry>
        <mesh
          filename="package://URDF_Silvia_collision.SLDASM/meshes/RR_Femur.STL" />
      </geometry>
    </collision>
  </link>
  <joint
    name="RR_Femur"
    type="revolute">
    <origin
      xyz="0.0569999999999997 0.000500000000000034 0"
      rpy="1.5707963267949 6.65905161136378E-16 -1.01030295240889E-14" />
    <parent
      link="RR_Coxa" />
    <child
      link="RR_Femur" />
    <axis
      xyz="0 0 1" />
  </joint>
  <link
    name="RR_Tibia">
    <inertial>
      <origin
        xyz="0 -0.131709927052439 -4.33680868994202E-18"
        rpy="0 0 0" />
      <mass
        value="0.272494368622691" />
      <inertia
        ixx="0.00410733533858373"
        ixy="1.04480438173758E-19"
        ixz="-1.0842021724855E-19"
        iyy="8.81242945143451E-05"
        iyz="-2.30789318587402E-19"
        izz="0.00404604861308373" />
    </inertial>
    <visual>
      <origin
        xyz="0 0 0"
        rpy="0 0 0" />
      <geometry>
        <mesh
          filename="package://URDF_Silvia_collision.SLDASM/meshes/RR_Tibia.STL" />
      </geometry>
      <material
        name="">
        <color
          rgba="0.792156862745098 0.819607843137255 0.933333333333333 1" />
      </material>
    </visual>
    <collision>
      <origin
        xyz="0 0 0"
        rpy="0 0 0" />
      <geometry>
        <mesh
          filename="package://URDF_Silvia_collision.SLDASM/meshes/RR_Tibia.STL" />
      </geometry>
    </collision>
  </link>
  <joint
    name="RR_Tibia"
    type="revolute">
    <origin
      xyz="0.197499999999995 -0.0264999999999868 -0.000500000000000025"
      rpy="1.5043318639474E-16 2.77555756156289E-16 3.1922744524727E-16" />
    <parent
      link="RR_Femur" />
    <child
      link="RR_Tibia" />
    <axis
      xyz="0 0 1" />
  </joint>
  <link
    name="LR_Coxa">
    <inertial>
      <origin
        xyz="0.034 0 -6.93889390390723E-18"
        rpy="0 0 0" />
      <mass
        value="0.1274" />
      <inertia
        ixx="9.62400833333333E-05"
        ixy="3.38813178901721E-21"
        ixz="8.24810675700223E-21"
        iyy="0.000114458283333333"
        iyz="1.16407031888381E-20"
        izz="3.48651333333334E-05" />
    </inertial>
    <visual>
      <origin
        xyz="0 0 0"
        rpy="0 0 0" />
      <geometry>
        <mesh
          filename="package://URDF_Silvia_collision.SLDASM/meshes/LR_Coxa.STL" />
      </geometry>
      <material
        name="">
        <color
          rgba="0.792156862745098 0.819607843137255 0.933333333333333 1" />
      </material>
    </visual>
    <collision>
      <origin
        xyz="0 0 0"
        rpy="0 0 0" />
      <geometry>
        <mesh
          filename="package://URDF_Silvia_collision.SLDASM/meshes/LR_Coxa.STL" />
      </geometry>
    </collision>
  </link>
  <joint
    name="LR_Coxa"
    type="revolute">
    <origin
      xyz="-0.110395052406575 -0.192013984860853 -0.0411000000000001"
      rpy="2.90792643314256E-16 -1.52655665885959E-16 -2.09439510239319" />
    <parent
      link="torso" />
    <child
      link="LR_Coxa" />
    <axis
      xyz="0 0 1" />
  </joint>
  <link
    name="LR_Femur">
    <inertial>
      <origin
        xyz="0.10975 2.08166817117217E-17 -2.77555756156289E-17"
        rpy="0 0 0" />
      <mass
        value="0.750031499999999" />
      <inertia
        ixx="0.000552588207729999"
        ixy="-1.02101450892145E-18"
        ixz="4.87890977618477E-19"
        iyy="0.00346297356378125"
        iyz="4.01499410324917E-20"
        izz="0.00311239884026124" />
    </inertial>
    <visual>
      <origin
        xyz="0 0 0"
        rpy="0 0 0" />
      <geometry>
        <mesh
          filename="package://URDF_Silvia_collision.SLDASM/meshes/LR_Femur.STL" />
      </geometry>
      <material
        name="">
        <color
          rgba="0.792156862745098 0.819607843137255 0.933333333333333 1" />
      </material>
    </visual>
    <collision>
      <origin
        xyz="0 0 0"
        rpy="0 0 0" />
      <geometry>
        <mesh
          filename="package://URDF_Silvia_collision.SLDASM/meshes/LR_Femur.STL" />
      </geometry>
    </collision>
  </link>
  <joint
    name="LR_Femur"
    type="revolute">
    <origin
      xyz="0.0569999999999997 0.000499999999999891 0"
      rpy="1.5707963267949 9.85322934354823E-16 -1.07136521876328E-14" />
    <parent
      link="LR_Coxa" />
    <child
      link="LR_Femur" />
    <axis
      xyz="0 0 1" />
  </joint>
  <link
    name="LR_Tibia">
    <inertial>
      <origin
        xyz="0 -0.131709927052439 -3.51281503885303E-17"
        rpy="0 0 0" />
      <mass
        value="0.27249436862269" />
      <inertia
        ixx="0.00410733533858373"
        ixy="2.2709092371145E-19"
        ixz="1.08420217248551E-19"
        iyy="8.81242945143449E-05"
        iyz="-1.16787274160764E-18"
        izz="0.00404604861308373" />
    </inertial>
    <visual>
      <origin
        xyz="0 0 0"
        rpy="0 0 0" />
      <geometry>
        <mesh
          filename="package://URDF_Silvia_collision.SLDASM/meshes/LR_Tibia.STL" />
      </geometry>
      <material
        name="">
        <color
          rgba="0.792156862745098 0.819607843137255 0.933333333333333 1" />
      </material>
    </visual>
    <collision>
      <origin
        xyz="0 0 0"
        rpy="0 0 0" />
      <geometry>
        <mesh
          filename="package://URDF_Silvia_collision.SLDASM/meshes/LR_Tibia.STL" />
      </geometry>
    </collision>
  </link>
  <joint
    name="LR_Tibia"
    type="revolute">
    <origin
      xyz="0.197499999999995 -0.026499999999987 -0.000500000000000265"
      rpy="-7.5829642775218E-17 6.66133814775094E-16 5.55111512312578E-16" />
    <parent
      link="LR_Femur" />
    <child
      link="LR_Tibia" />
    <axis
      xyz="0 0 1" />
  </joint>
  <link
    name="LM_Coxa">
    <inertial>
      <origin
        xyz="0.034 -1.0842021724855E-18 -6.93889390390723E-18"
        rpy="0 0 0" />
      <mass
        value="0.1274" />
      <inertia
        ixx="9.62400833333332E-05"
        ixy="1.21903829695789E-21"
        ixz="1.57612665821863E-20"
        iyy="0.000114458283333333"
        iyz="1.08602093205561E-20"
        izz="3.48651333333333E-05" />
    </inertial>
    <visual>
      <origin
        xyz="0 0 0"
        rpy="0 0 0" />
      <geometry>
        <mesh
          filename="package://URDF_Silvia_collision.SLDASM/meshes/LM_Coxa.STL" />
      </geometry>
      <material
        name="">
        <color
          rgba="0.792156862745098 0.819607843137255 0.933333333333333 1" />
      </material>
    </visual>
    <collision>
      <origin
        xyz="0 0 0"
        rpy="0 0 0" />
      <geometry>
        <mesh
          filename="package://URDF_Silvia_collision.SLDASM/meshes/LM_Coxa.STL" />
      </geometry>
    </collision>
  </link>
  <joint
    name="LM_Coxa"
    type="revolute">
    <origin
      xyz="-0.221136515003529 -0.000604145171771042 -0.0411"
      rpy="3.13661300568136E-16 -4.57966997657893E-16 -3.14159265358976" />
    <parent
      link="torso" />
    <child
      link="LM_Coxa" />
    <axis
      xyz="0 0 1" />
  </joint>
  <link
    name="LM_Femur">
    <inertial>
      <origin
        xyz="0.10975 3.46944695195361E-17 -2.16840434497101E-18"
        rpy="0 0 0" />
      <mass
        value="0.750031499999999" />
      <inertia
        ixx="0.000552588207729999"
        ixy="-7.50196724021888E-19"
        ixz="6.90299918498244E-20"
        iyy="0.00346297356378124"
        iyz="3.65346937266987E-20"
        izz="0.00311239884026125" />
    </inertial>
    <visual>
      <origin
        xyz="0 0 0"
        rpy="0 0 0" />
      <geometry>
        <mesh
          filename="package://URDF_Silvia_collision.SLDASM/meshes/LM_Femur.STL" />
      </geometry>
      <material
        name="">
        <color
          rgba="0.792156862745098 0.819607843137255 0.933333333333333 1" />
      </material>
    </visual>
    <collision>
      <origin
        xyz="0 0 0"
        rpy="0 0 0" />
      <geometry>
        <mesh
          filename="package://URDF_Silvia_collision.SLDASM/meshes/LM_Femur.STL" />
      </geometry>
    </collision>
  </link>
  <joint
    name="LM_Femur"
    type="revolute">
    <origin
      xyz="0.0569999999999997 0.000499999999999926 0"
      rpy="1.5707963267949 5.81657889231598E-16 -1.03111963412077E-14" />
    <parent
      link="LM_Coxa" />
    <child
      link="LM_Femur" />
    <axis
      xyz="0 0 1" />
  </joint>
  <link
    name="LM_Tibia">
    <inertial>
      <origin
        xyz="0 -0.131709927052439 -5.65953534037433E-17"
        rpy="0 0 0" />
      <mass
        value="0.27249436862269" />
      <inertia
        ixx="0.00410733533858373"
        ixy="-2.89417263567462E-19"
        ixz="-3.21787577013275E-21"
        iyy="8.81242945143449E-05"
        iyz="-7.96083026083569E-19"
        izz="0.00404604861308373" />
    </inertial>
    <visual>
      <origin
        xyz="0 0 0"
        rpy="0 0 0" />
      <geometry>
        <mesh
          filename="package://URDF_Silvia_collision.SLDASM/meshes/LM_Tibia.STL" />
      </geometry>
      <material
        name="">
        <color
          rgba="0.792156862745098 0.819607843137255 0.933333333333333 1" />
      </material>
    </visual>
    <collision>
      <origin
        xyz="0 0 0"
        rpy="0 0 0" />
      <geometry>
        <mesh
          filename="package://URDF_Silvia_collision.SLDASM/meshes/LM_Tibia.STL" />
      </geometry>
    </collision>
  </link>
  <joint
    name="LM_Tibia"
    type="revolute">
    <origin
      xyz="0.197499999999994 -0.0264999999999877 -0.00049999999998687"
      rpy="2.447921408846E-16 4.16333634241786E-17 4.17207842060058E-17" />
    <parent
      link="LM_Femur" />
    <child
      link="LM_Tibia" />
    <axis
      xyz="0 0 1" />
  </joint>
  <link
    name="LF_Coxa">
    <inertial>
      <origin
        xyz="0.0339999999999999 0 6.93889390390723E-18"
        rpy="0 0 0" />
      <mass
        value="0.1274" />
      <inertia
        ixx="9.62400833333332E-05"
        ixy="1.35525271560688E-20"
        ixz="7.61631805321468E-21"
        iyy="0.000114458283333333"
        iyz="-1.37532713184278E-21"
        izz="3.48651333333333E-05" />
    </inertial>
    <visual>
      <origin
        xyz="0 0 0"
        rpy="0 0 0" />
      <geometry>
        <mesh
          filename="package://URDF_Silvia_collision.SLDASM/meshes/LF_Coxa.STL" />
      </geometry>
      <material
        name="">
        <color
          rgba="0.792156862745098 0.819607843137255 0.933333333333333 1" />
      </material>
    </visual>
    <collision>
      <origin
        xyz="0 0 0"
        rpy="0 0 0" />
      <geometry>
        <mesh
          filename="package://URDF_Silvia_collision.SLDASM/meshes/LF_Coxa.STL" />
      </geometry>
    </collision>
  </link>
  <joint
    name="LF_Coxa"
    type="revolute">
    <origin
      xyz="-0.110741462568097 0.191005694483978 -0.0411"
      rpy="3.91752055435901E-16 -7.73686670285656E-16 2.09439510239324" />
    <parent
      link="torso" />
    <child
      link="LF_Coxa" />
    <axis
      xyz="0 0 1" />
  </joint>
  <link
    name="LF_Femur">
    <inertial>
      <origin
        xyz="0.10975 3.46944695195361E-17 4.16333634234434E-17"
        rpy="0 0 0" />
      <mass
        value="0.750031499999998" />
      <inertia
        ixx="0.000552588207729998"
        ixy="-8.39870289427459E-19"
        ixz="-4.6078592330634E-19"
        iyy="0.00346297356378124"
        iyz="5.48018608142116E-20"
        izz="0.00311239884026124" />
    </inertial>
    <visual>
      <origin
        xyz="0 0 0"
        rpy="0 0 0" />
      <geometry>
        <mesh
          filename="package://URDF_Silvia_collision.SLDASM/meshes/LF_Femur.STL" />
      </geometry>
      <material
        name="">
        <color
          rgba="0.792156862745098 0.819607843137255 0.933333333333333 1" />
      </material>
    </visual>
    <collision>
      <origin
        xyz="0 0 0"
        rpy="0 0 0" />
      <geometry>
        <mesh
          filename="package://URDF_Silvia_collision.SLDASM/meshes/LF_Femur.STL" />
      </geometry>
    </collision>
  </link>
  <joint
    name="LF_Femur"
    type="revolute">
    <origin
      xyz="0.0569999999999997 0.000499999999999884 0"
      rpy="1.5707963267949 3.85108611666847E-16 -1.10467190950203E-14" />
    <parent
      link="LF_Coxa" />
    <child
      link="LF_Femur" />
    <axis
      xyz="0 0 1" />
  </joint>
  <link
    name="LF_Tibia">
    <inertial>
      <origin
        xyz="5.55111512312578E-17 -0.131709927052439 -4.81385764583564E-17"
        rpy="0 0 0" />
      <mass
        value="0.27249436862269" />
      <inertia
        ixx="0.00410733533858373"
        ixy="-1.65934204266786E-19"
        ixz="-1.08420217248551E-19"
        iyy="8.8124294514345E-05"
        iyz="-1.12309960419516E-18"
        izz="0.00404604861308373" />
    </inertial>
    <visual>
      <origin
        xyz="0 0 0"
        rpy="0 0 0" />
      <geometry>
        <mesh
          filename="package://URDF_Silvia_collision.SLDASM/meshes/LF_Tibia.STL" />
      </geometry>
      <material
        name="">
        <color
          rgba="0.792156862745098 0.819607843137255 0.933333333333333 1" />
      </material>
    </visual>
    <collision>
      <origin
        xyz="0 0 0"
        rpy="0 0 0" />
      <geometry>
        <mesh
          filename="package://URDF_Silvia_collision.SLDASM/meshes/LF_Tibia.STL" />
      </geometry>
    </collision>
  </link>
  <joint
    name="LF_Tibia"
    type="revolute">
    <origin
      xyz="0.197499999999995 -0.0264999999999869 -0.000500000000000329"
      rpy="-3.28814406739269E-16 7.7715611723761E-16 4.99600361081318E-16" />
    <parent
      link="LF_Femur" />
    <child
      link="LF_Tibia" />
    <axis
      xyz="0 0 1" />
  </joint>
</robot>